Traceback (most recent call last):
  File "C:\Users\shira\AppData\Local\Temp/ipykernel_25008/4199430361.py", line 25, in <module>
    raise Exception("これはエラーメッセージです。")
Exception: これはエラーメッセージです。
